<?xml version="1.0"?>
<robot xmlns:xacro="http://www.ros.org/wiki/xacro">

    <!-- Transmission Macro -->
    <!-- <xacro:macro name="simple_transmission" params="joint">
        <transmission name="${joint}_trans">
            <type>transmission_interface/SimpleTransmission</type>
            <joint name="${joint}">
                <hardwareInterface>hardware_interface/EffortJointInterface</hardwareInterface>
            </joint>
            <actuator name="${joint}_motor">
                <hardwareInterface>hardware_interface/EffortJointInterface</hardwareInterface>
                <mechanicalReduction>1</mechanicalReduction>
            </actuator>
        </transmission>
    </xacro:macro> -->


    <!-- Transmission Macro -->
    <xacro:macro name="simple_transmission" params="joint">
      <transmission name="${joint}_trans">
        <type>transmission_interface/SimpleTransmission</type>
        <joint name="${joint}">
          <hardwareInterface>hardware_interface/PositionJointInterface</hardwareInterface>
        </joint>
        <actuator name="${joint}_motor">
          <!-- <hardwareInterface>EffortJointInterface</hardwareInterface> -->
          <mechanicalReduction>1</mechanicalReduction>
        </actuator>
      </transmission>
    </xacro:macro>



    <xacro:macro name="alpha_arm" params="namespace">


        <material name="black_arm">
        <color rgba="0 0 0 1"/>
        </material>

        <link name="${namespace}/base_link">
            <visual>
                <geometry>
                    <mesh filename="package://alpha_description/meshes/reach5mini/visual/Base.stl" />
                </geometry>
                <origin rpy="0 0 0" xyz="0 0 0"/>
                <material name="black_arm"/>
            </visual>
            <collision>
                <geometry>
                    <cylinder length="0.150" radius="0.020"/>
                </geometry>
                <origin rpy="0 1.57075 0" xyz="-0.075 0 0"/>
            </collision>
            <inertial>
                <mass value="0.341"/>
                <origin xyz="-0.075 -0.006 -0.003"/>
                <inertia ixx="0.000099" ixy="0.000139" ixz="0.000115" iyy="0.002920" iyz="0.000003" izz="0.002934"/>
                <!-- <inertia ixx="${(1/12)*0.341*(0.150)**2 + 0.25*0.341*0.020**2}" ixy="0.0" ixz="0.0" 
                iyy="${(1/12)*0.341*(0.150)**2 + 0.25*0.341*0.020**2}" iyz="0.0" 
                izz="${0.5*0.341*0.020**2}"/> -->
            </inertial>
        </link>
        
        <link name="${namespace}/shoulder_link">
            <visual>
            <geometry>
                <mesh filename="package://alpha_description/meshes/reach5mini/visual/ShoulderJoint.stl" />
            </geometry>
            <material name="black_arm"/>
            <origin rpy="0 0 -1.57075" xyz="0 0 0"/>
            </visual>
            <collision>
            <geometry>
                <cylinder length="0.066" radius="0.020"/>
            </geometry>
            <origin rpy="0 0 0" xyz="0 0 0.010"/>
            </collision>
            <inertial>
            <mass value="0.194"/>
            <origin xyz="0.005 -0.001 0.016"/>
            <!-- <inertia ixx="0.000189" ixy="0.000005" ixz="0.000054" iyy="0.000213" iyz="0.000003" izz="0.000067"/> -->
            <inertia ixx="${(1/12)*0.194*(0.066)**2 + 0.25*0.194*0.020**2}" ixy="0.0" ixz="0.0" 
            iyy="${(1/12)*0.194*(0.066)**2 + 0.25*0.194*0.020**2}" iyz="0.0" 
            izz="${0.5*0.194*0.020**2}"/>
            </inertial>
        </link>
            
        <link name="${namespace}/upper_arm_link">
            <visual>
            <geometry>
                <mesh filename="package://alpha_description/meshes/reach5mini/visual/UpperArm.stl" />
            </geometry>
            <origin rpy="0 -1.57075 -0.2655555" xyz="0 0 -0.075"/>
            <material name="black_arm"/>
            </visual>
            <collision>
            <geometry>
                <cylinder length="0.1445" radius="0.020"/>
            </geometry>
            <origin rpy="0 1.57075 -0.27075" xyz="0.075 0 0"/>
            </collision>
            <collision>
            <geometry>
                <cylinder length="0.040" radius="0.020"/>
            </geometry>
            <origin rpy="0 0 0" xyz="0 0 0"/>    
            </collision>
            <inertial>
            <mass value="0.429"/>
            <origin xyz="0.073 0.0 0.0"/>
            <!-- <inertia ixx="0.000087" ixy="-0.000076" ixz="-0.000010" iyy="0.003190" iyz="0.000000" izz="0.003213"/> -->
            <inertia ixx="${(1/12)*0.429*(0.040)**2 + 0.25*0.429*0.020**2}" ixy="0.25" ixz="0.0" 
            iyy="${(1/12)*0.429*(0.040)**2 + 0.25*0.429*0.020**2}" iyz="0.0" 
            izz="${0.5*0.429*0.020**2}"/>
            </inertial>
        </link>

        <link name="${namespace}/forearm_link">
            <visual>
            <geometry>
                <mesh filename="package://alpha_description/meshes/reach5mini/visual/ForearmJoint.stl" />
            </geometry>
            <origin rpy="0 0 0" xyz="0 0 0"/>
            <material name="black_arm"/>
            </visual>
            <collision>
            <geometry>
                <cylinder length="0.040" radius="0.020"/>
            </geometry>
            <origin rpy="0 0 0" xyz="0 0 0"/>
            </collision>
            <inertial>
            <mass value="0.115"/>
            <origin xyz="0.017 -0.026 -0.002"/>
            <!-- <inertia ixx="0.000120" ixy="-0.000061" ixz="-0.000001" iyy="0.000062" iyz="0.000000" izz="0.000156"/> -->
            <inertia ixx="${(1/12)*0.115*(0.040)**2 + 0.25*0.115*0.020**2}" ixy="0.0" ixz="0.0" 
            iyy="${(1/12)*0.115*(0.040)**2 + 0.25*0.115*0.020**2}" iyz="0.0" 
            izz="${0.5*0.115*0.020**2}"/>
            </inertial>
        </link>	

        <link name="${namespace}/wrist_link">
            <visual>
            <geometry>
                <mesh filename="package://alpha_description/meshes/reach5mini/visual/Wrist.stl" />
            </geometry>
            <origin rpy="0 0 0" xyz="0 0 0"/>
            <material name="black_arm"/>
            </visual>
            <collision>
            <geometry>
                <cylinder length="0.140" radius="0.020"/>
            </geometry>
            <origin rpy="0 0 0" xyz="0 0 -0.070"/>
            </collision>
            <inertial>
            <mass value="0.333"/>
            <origin xyz="0.0 0.003 -0.098"/>
            <!-- <inertia ixx="0.003709" ixy="-0.000002" ixz="-0.000004" iyy="0.003734" iyz="0.000000" izz="0.000079"/> -->
            <inertia ixx="${(1/12)*0.333*(0.040)**2 + 0.25*0.333*0.140**2}" ixy="0.0" ixz="0.0" 
            iyy="${(1/12)*0.333*(0.040)**2 + 0.25*0.333*0.140**2}" iyz="0.0" 
            izz="${0.5*0.333*0.140**2}"/>
            </inertial>
        </link>

        <!-- <link name="${namespace}/tip">
        </link> -->
        
        <link name="${namespace}/jaw1">
            <visual>
                <geometry>
                    <mesh filename="package://alpha_description/meshes/reach5mini/visual/Jaw1.stl" />
                </geometry>
                <origin rpy="0 0 0" xyz="0 0 0"/>
                <material name="black_arm"/>
            </visual>
            <collision>
                <geometry>
                    <mesh filename="package://alpha_description/meshes/reach5mini/visual/Jaw1.stl" scale="1 1 0.9"/>                        
                </geometry>
            </collision>
            <!-- <collision> -->
                <!-- <origin rpy="0 0 0" xyz="0 0 0"/> -->
                <!-- <geometry>
                    <mesh filename="package://alpha_description/meshes/reach5mini/visual/Jaw1.stl" scale="1 1 0.9"/>
                </geometry>                 -->
                <!-- <geometry>
                    <box size="0.02 0.07 0.01"/>
                </geometry>
                <origin rpy="0 0 0" xyz="-0.04 -0.045 0"/> -->
            <!-- </collision> -->
            <!-- Made up inertias from wrist -->
            <inertial>
                <mass value="0.333"/>
                <origin xyz="0.0 0.003 -0.098"/>
                <!-- <inertia ixx="0.003709" ixy="-0.000002" ixz="-0.000004" iyy="0.003734" iyz="0.0" izz="0.000079"/> -->
                <inertia ixx="${1/12*0.333*(0.09**2+0.01**2)}" ixy="0.0" ixz="-0.0" 
                iyy="${1/12*0.333*(0.03**2+0.01**2)}" iyz="0.0" 
                izz="${1/12*0.333*(0.03**2+0.09**2)}"/>
            </inertial>
        </link>

        <link name="${namespace}/jaw2">
            <visual>
                <geometry>
                    <mesh filename="package://alpha_description/meshes/reach5mini/visual/Jaw2.stl" />
                </geometry>
                <origin rpy="0 0 0" xyz="0 0 0"/>
                <material name="black_arm"/>      
            </visual>
            <collision>
                <geometry>
                    <mesh filename="package://alpha_description/meshes/reach5mini/visual/Jaw2.stl" scale="1 1 0.9"/>
                </geometry>
            </collision>
            <!-- <collision> -->
                <!-- <geometry>
                    <mesh filename="package://alpha_description/meshes/reach5mini/visual/Jaw2.stl" scale="1 1 0.9"/>
                </geometry> -->

                <!-- <origin rpy="0 0 0" xyz="0 0 0"/>
                <geometry>
                    <box size="0.02 0.07 0.01"/>
                </geometry>
                <origin rpy="0 0 0" xyz="0.01 -0.045 0"/>
                <origin rpy="0 0 0" xyz="0.04 -0.045 0"/> -->
            <!-- </collision> -->
            <!-- Made up inertias from wrist -->
            <inertial>
            <mass value="0.333"/>
            <origin xyz="0.0 0.003 -0.098"/>
            <!-- <inertia ixx="0.003709" ixy="-0.00002" ixz="-0.00004" iyy="0.003734" iyz="0.0" izz="0.000079"/> -->
            <inertia ixx="${1/12*0.333*(0.09**2+0.01**2)}" ixy="0.0" ixz="-0.0" 
            iyy="${1/12*0.333*(0.03**2+0.01**2)}" iyz="0.0" 
            izz="${1/12*0.333*(0.03**2+0.09**2)}"/>
            </inertial>
        </link>

        <joint name="${namespace}/joint1" type="revolute">
            <parent link="${namespace}/base_link"/>
            <child link="${namespace}/shoulder_link"/>
            <origin xyz="0 0 0" rpy="0 0 0"/> <!--Was <origin xyz="0 0 0" rpy="0 0 3.141592/> before-->
            <axis xyz="0 0 1"/>
            <limit effort="9.0" lower="-${pi}" upper = "${pi}" velocity="0.5"/>
            <dynamics damping="0.1" friction="0.1"/>
        </joint>
        <xacro:simple_transmission joint="${namespace}/joint1" />

        <joint name="${namespace}/joint2" type="revolute">
            <parent link="${namespace}/shoulder_link"/>
            <child link="${namespace}/upper_arm_link"/> 
            <origin xyz="0.020 0 0.046" rpy="1.57075 1.3 0"/>
            <!-- <origin xyz="0.020 0 0.046" rpy="1.57075 0 0"/> -->
            <axis xyz="0 0 1"/>
            <limit effort="9.0" lower="0.0" upper = "3.5" velocity="0.5"/>
            <dynamics damping="0.1" friction="0.1"/>
        </joint>
        <xacro:simple_transmission joint="${namespace}/joint2" />

        <joint name="${namespace}/joint3" type="revolute">
            <parent link="${namespace}/upper_arm_link"/>
            <child link="${namespace}/forearm_link"/>
            <origin xyz="0.15 0 0" rpy="3.1415 0 1.3"/>
            <!-- <origin xyz="0.15 0 0" rpy="3.1415 0 ${-pi/2}"/> -->
            <axis xyz="0 0 1"/>
            <limit effort="9.0" lower="0.0" upper = "3.5" velocity="0.5"/>
            <dynamics damping="0.1" friction="0.1"/>
        </joint>
        <xacro:simple_transmission joint="${namespace}/joint3" />

        <joint name="${namespace}/joint4" type="revolute">
            <parent link="${namespace}/forearm_link"/>
            <child link="${namespace}/wrist_link"/>
            <origin xyz="0.020 0 0" rpy="-1.57075 0 0"/>
            <axis xyz="0 0 1"/>
            <limit effort="5.0" lower="${-pi}" upper = "${pi}" velocity="1.0"/>
            <dynamics damping="0.1" friction="0.1"/>
        </joint>
        <xacro:simple_transmission joint="${namespace}/joint4" />

        <joint name="${namespace}/joint5" type="revolute">
            <parent link="${namespace}/wrist_link"/>
            <child link="${namespace}/jaw1"/>
            <origin xyz="0.015 0 -0.140" rpy="1.57075 0 0"/>
            <axis xyz="0 0 1"/>
            <limit effort="5.0" lower="0.0" upper = "0.5" velocity="0.5"/>
            <dynamics damping="0.1" friction="0.1"/>
        </joint>
        <xacro:simple_transmission joint="${namespace}/joint5" />

        <joint name="${namespace}/joint6" type="revolute">
            <parent link="${namespace}/wrist_link"/>
            <child link="${namespace}/jaw2"/>
            <origin xyz="-0.015 0 -0.140" rpy="1.57075 0 0"/>
            <axis xyz="0 0 -1"/>
            <limit effort="5.0" lower="0.0" upper = "0.5" velocity="0.5"/>
            <dynamics damping="0.1" friction="0.1"/>
        </joint>
        <xacro:simple_transmission joint="${namespace}/joint6" />

        <!-- <joint name="${namespace}/arm_to_tip" type="fixed">
            <parent link="${namespace}/wrist_link"/>
            <child link="${namespace}/tip"/>
            <origin xyz="0 0 -0.180" rpy="0 1.57075 0"/>
        </joint> -->
  
        
        <!-- <xacro:alpha_gazebo_arm namespace="${namespace}"/> -->
    </xacro:macro>
</robot>
